Workbook

Sheet Summary
A1: Project | B1: GPP Scan and Shop
A2: Document | B2: Customer Account Creation — Manual Test Specification (from customer-account-creation-test-cases.xml)
A3: Generated | B3: 2026-07-28
A4: Author | B4: GPP QA Team
A6: Sub-module | B6: Stories | C6: Test Cases | D6: In Scope | E6: Passed | F6: Failed | G6: Pending | H6: Blocked | I6: Not test | J6: Blank | K6: % Progress | L6: % Pass Rate
A7: Customer Account Creation | B7: 1 | C7: ='a. Customer Account Creation'!F1 | D7: =C7-I7 | E7: =COUNTIF('a. Customer Account Creation'!L:L,"Passed") | F7: =COUNTIF('a. Customer Account Creation'!L:L,"Failed") | G7: =COUNTIF('a. Customer Account Creation'!L:L,"Pending") | H7: =COUNTIF('a. Customer Account Creation'!L:L,"Blocked") | I7: =COUNTIF('a. Customer Account Creation'!L:L,"Not test") | J7: =COUNTIFS('a. Customer Account Creation'!B:B,"TC-*",'a. Customer Account Creation'!L:L,"") | K7: =IF(D7=0,"N/A",(E7+F7+H7)/D7) | L7: =IF(D7=0,"N/A",E7/D7)
A17: TOTAL | B17: =SUM(B7:B16) | C17: =SUM(C7:C16) | D17: =SUM(D7:D16) | E17: =SUM(E7:E16) | F17: =SUM(F7:F16) | G17: =SUM(G7:G16) | H17: =SUM(H7:H16) | I17: =SUM(I7:I16) | J17: =SUM(J7:J16) | K17: =IF(D17=0,"N/A",(E17+F17+H17)/D17) | L17: =IF(D17=0,"N/A",E17/D17)

Sheet Config
A1: Lookup | B1: Values
A2: Priority | B2: High | C2: Medium | D2: Low
A3: Status | B3: Not test | C3: Passed | D3: Failed | E3: Pending | F3: Blocked
A4: Browser | B4: Chrome (latest) | C4: Safari (latest) | D4: Firefox (latest) | E4: Edge (latest)
A5: Default user | B5: Store Associate (Sam)
A6: Roles | B6: Store Associate (Sam) | C6: Customer (Olivia) | D6: Tailor / Fit Specialist (Tariq) | E6: Order / Brand Administrator (Bianca) | F6: Sizestream Administrator (Sid)

Sheet RTM (Detail BRD)
A1: Project | B1: GPP Scan and Shop
A2: Document | B2: Internal_Scan_And_Shop_BRD.md (BRD-SS-001 v1.8) — detail-BRD traceability
A3: Generated | B3: 2026-07-28
A5: Detail Story ID | B5: Title | C5: Coverage | D5: Sheet | E5: Overview Equivalent
A6: FR-01 / §1.0-1.2 | B6: Open Account Creation form in Insert mode with brand context | C6: TC-036, TC-029 | D6: a. Customer Account Creation | E6: US-CI-03
A7: FR-02 / §2 | B7: Capture Contact Information fields | C7: TC-001, TC-007, TC-035 | D7: a. Customer Account Creation | E7: US-CI-06
A8: FR-03 / §2 | B8: Capture Address Information fields | C8: TC-007, TC-035 | D8: a. Customer Account Creation | E8: US-CI-06
A9: FR-04 / §5.1 #50 | B9: First Name required | C9: TC-002, TC-018 | D9: a. Customer Account Creation | E9: US-CI-06
A10: FR-05 / §5.1 #60 | B10: Last Name required | C10: TC-003, TC-018 | D10: a. Customer Account Creation | E10: US-CI-06
A11: FR-06 / §5.1 #30 | B11: Email required (not null) | C11: TC-004, TC-029 | D11: a. Customer Account Creation | E11: US-CI-06
A12: FR-07 / §5.1 #70 | B12: Email format valid | C12: TC-005, TC-006, TC-019, TC-037 | D12: a. Customer Account Creation | E12: US-CI-06
A13: FR-08 / §5.1 #80 | B13: Email unique within brand | C13: TC-020, TC-025, TC-026, TC-038 | D13: a. Customer Account Creation | E13: US-CI-06
A14: FR-09 / §5.1 #10 | B14: Home Phone minimum 10 digits | C14: TC-011, TC-012, TC-013, TC-021, TC-039 | D14: a. Customer Account Creation | E14: US-CI-06
A15: FR-10 / §5.1 #20 | B15: Mobile Phone minimum 10 digits | C15: TC-014, TC-015, TC-016, TC-039 | D15: a. Customer Account Creation | E15: US-CI-06
A16: FR-11 / §2 | B16: Default Gender = Male | C16: TC-009, TC-022, TC-024 | D16: a. Customer Account Creation | E16: US-CI-06
... A23: FR-18 / R5 | B23: Terms acceptance de-scoped (no Terms UI; Save not Terms-gated) | C23: TC-033, TC-034 | D23: a. Customer Account Creation | E23: US-CI-06

Sheet a. Customer Account Creation
A1: Project task | B1: GPP Scan and Shop | E1: Total | F1: =SUM(F2:F4) | G1: =F1/$F$1 | I1: Result
A2: Uploaded Date | B2: 2026-07-28 | E2: High | F2: =COUNTIF($J$5:$J$970,E2) | G2: =F2/$F$1 | I2: Passed | J2: =COUNTIF($L:$L,I2)
E3: Medium | F3: =COUNTIF($J$5:$J$970,E3) | G3: =F3/$F$1 | I3: Failed | J3: =COUNTIF($L:$L,I3)
E4: Low | F4: =COUNTIF($J$5:$J$970,E4) | G4: =F4/$F$1 | I4: Pending | J4: =COUNTIF($L:$L,I4)
I5: Blocked | J5: =COUNTIF($L:$L,I5)
I6: Not test | J6: =COUNTIF($L:$L,I6)
I7: Total | J7: =SUM(J2:J6)
A9: StoriesID | B9: Test cases ID | C9: Description | D9: Pre-Condition | E9: Browser | F9: Test Steps | G9: Test Data | H9: Expected Result | I9: Actual Result | J9: Priority | K9: PIC Test | L9: Status | M9: PIC Dev | N9: EVD | O9: Bug ID
A10: Equivalence Partitioning — field partitions, defaults, uniqueness & R5 checks
A11: US-CI-06 | B11: TC-001 | C11: Create customer with all valid mandatory fields and default Gender/Country Technique: Equivalence Partitioning Req: US-CI-06; Customer Detail §2 (Controls), §5.1 (Save Customer Details); FR-16, FR-11, FR-12 | D11: Account Creation form open in Insert mode with brand context set (AS-03). No existing customer with the test email in the current brand. | E11: Chrome (latest) | F11: 1. Enter First and Last Name. 2. Enter a valid, brand-unique Email. 3. Leave Gender and Country at defaults. 4. Click Save. | G11: First Name = "John"; Last Name = "Miller"; Email = "john.miller@example.com"; Gender = Male (default); Country = United States of America (default); optional fields blank. | H11: All 8 validations pass; the Customer is committed and stamped to the current brand (BrandID = CurrentOrderBrandID); a CustomerBrand link is created; UserParam.CurrentCustomerID is set to the new customer and the flow continues with that customer selected (AS-07). | J11: High
A12: US-CI-06 | B12: TC-002 | C12: Reject creation when First Name is empty Technique: Equivalence Partitioning Req: Customer Detail §5.1 validation #50 "First Name Missing"; FR-04 | D12: Account Creation form open in Insert mode (AS-03). | E12: Chrome (latest) | F12: 1. Leave First Name empty. 2. Enter a valid Last Name and Email. 3. Click Save. | G12: First Name = "" (empty); Last Name = "Miller"; Email = "john.miller@example.com". | H12: Save is blocked by validation #50 "First Name Missing"; no customer is created; the user remains on the form (message text unspecified — RG-05). | J12: High
A13: US-CI-06 | B13: TC-003 | C13: Reject creation when Last Name is empty Technique: Equivalence Partitioning Req: Customer Detail §5.1 validation #60 "Last Name Missing"; FR-05 | D13: Account Creation form open in Insert mode (AS-03). | E13: Chrome (latest) | F13: 1. Enter a valid First Name and Email. 2. Leave Last Name empty. 3. Click Save. | G13: First Name = "John"; Last Name = "" (empty); Email = "john.miller@example.com". | H13: Save is blocked by validation #60 "Last Name Missing"; no customer is created; the user remains on the form. | J13: High
A14: US-CI-06 | B14: TC-004 | C14: Reject creation when Email is empty (Email required) Technique: Equivalence Partitioning Req: Customer Detail §5.1 validation #30 "Email Address IS NULL"; FR-06 | D14: Account Creation form open in Insert mode (AS-03). | E14: Chrome (latest) | F14: 1. Enter valid First and Last Name. 2. Leave Email empty. 3. Click Save. | G14: First Name = "John"; Last Name = "Miller"; Email = "" (empty). | H14: Save is blocked by validation #30 "Email Address IS NULL"; no customer is created; the user remains on the form. | J14: High
A15: US-CI-06 | B15: TC-005 | C15: Reject creation when Email format is invalid Technique: Equivalence Partitioning Req: Customer Detail §5.1 validation #70 "email address format"; FR-07 | D15: Account Creation form open in Insert mode (AS-03). | E15: Chrome (latest) | F15: 1. Enter valid First and Last Name. 2. Enter an Email that does not match a valid structure. 3. Click Save. | G15: First Name = "John"; Last Name = "Miller"; Email = "john.miller.example.com" (no @, invalid-format partition per AS-04). | H15: Save is blocked by validation #70 "email address format"; no customer is created; the user remains on the form. | J15: High
A16: US-CI-06 | B16: TC-006 | C16: Accept a representative valid Email (valid-format partition) Technique: Equivalence Partitioning Req: Customer Detail §5.1 validations #30, #70; FR-07 | D16: Account Creation form open in Insert mode (AS-03); email not already used in the current brand. | E16: Chrome (latest) | F16: 1. Enter valid First and Last Name. 2. Enter a well-formed, brand-unique Email. 3. Click Save. | G16: First Name = "Amara"; Last Name = "Okafor"; Email = "amara.okafor@sub.example.co". | H16: Format (#70) and null (#30) checks pass; the customer is created and stamped to the brand (subject to RG-09 on the exact format definition). | J16: Medium
A17: US-CI-06 | B17: TC-007 | C17: Create customer with all optional fields populated with valid data Technique: Equivalence Partitioning Req: Customer Detail §2 (optional Contact/Address fields), §5.1 actions #10/#20/#30; FR-02, FR-03, FR-13 | D17: Account Creation form open in Insert mode (AS-03). | E17: Chrome (latest) | F17: 1. Enter all mandatory fields. 2. Populate every optional field with valid values (phones with 10 digits). 3. Click Save. | G17: Mandatory: First = "Lee", Last = "Tran", Email = "lee.tran@example.com". Optional: Title = "Mr"; Home Phone = "2025550100"; Mobile Country Code = "+1"; Mobile Phone = "2025550111"; Address = "10 Main St"; City = "Austin"; State = "TX"; Postal Code = "78701"; Country = United States of America. | H17: All validations pass; the customer is created with contact and address details persisted; phones and country code are normalised on Save (actions #10, #20, #30). | J17: Medium
A18: US-CI-06 | B18: TC-008 | C18: Create customer with only mandatory fields (all optional fields blank) Technique: Equivalence Partitioning Req: Customer Detail §2 (optional fields); AS-02; FR-02, FR-03 | D18: Account Creation form open in Insert mode (AS-03); phone minimum-digit rule assumed to apply only when a value is entered (AS-02, RG-03). | E18: Chrome (latest) | F18: 1. Enter only the mandatory fields. 2. Leave Title, all phones, and all address fields blank. 3. Click Save. | G18: First = "Nina"; Last = "Roy"; Email = "nina.roy@example.com"; all optional fields blank; Gender/Country at defaults. | H18: Save succeeds; empty optional phone fields do not trigger the minimum-10-digit validations (AS-02); the customer is created and set as current. | J18: Medium
A19: US-CI-06 | B19: TC-009 | C19: Create customer with a non-default valid Gender value Technique: Equivalence Partitioning Req: Customer Detail §2 (Gender, default Male); FR-11; RG-08 | D19: Account Creation form open in Insert mode (AS-03); a non-default Gender value is available from Global Configuration (RG-08). | E19: Chrome (latest) | F19: 1. Enter mandatory fields. 2. Change Gender from the default Male to another valid value. 3. Click Save. | G19: First = "Sara"; Last = "Kim"; Email = "sara.kim@example.com"; Gender = a valid non-default value (e.g., Female). | H19: The selected Gender is accepted and persisted with the created customer (dependent on RG-08 for the valid value set). | J19: Medium
A20: US-CI-06 | B20: TC-010 | C20: Create customer with a non-default valid Country value Technique: Equivalence Partitioning Req: Customer Detail §2 (Country, default USA), §5.1 action #30; FR-12, FR-14; RG-08 | D20: Account Creation form open in Insert mode (AS-03); Country list available (Rest Countries; RG-08). | E20: Chrome (latest) | F20: 1. Enter mandatory fields. 2. Change Country from the default United States of America to another valid country. 3. Click Save. | G20: First = "Diego"; Last = "Alvarez"; Email = "diego.alvarez@example.com"; Country = a valid non-default value (e.g., Canada). | H20: The selected Country is accepted and persisted; the country-code normalisation action (#30) applies the corresponding brand/country code. | J20: Medium
A21: US-CI-06 | B21: TC-022 | C21: Gender defaults to Male on form open Technique: Equivalence Partitioning Req: Customer Detail §2 (Gender default = Male); FR-11 | D21: Account Creation form freshly opened in Insert mode (AS-03). | E21: Chrome (latest) | F21: 1. Open the Account Creation form. 2. Observe the Gender field before any input. | G21: None (observe default state). | H21: Gender is pre-selected as Male by default (§2). | J21: Medium
A22: US-CI-06 | B22: TC-023 | C22: Country defaults to United States of America on form open Technique: Equivalence Partitioning Req: Customer Detail §2 (Country default = United States of America); FR-12 | D22: Account Creation form freshly opened in Insert mode (AS-03). | E22: Chrome (latest) | F22: 1. Open the Account Creation form. 2. Observe the Country field before any input. | G22: None (observe default state). | H22: Country is pre-selected as United States of America by default (§2). | J22: Medium
... A29: US-CI-06 | B29: TC-034 | C29: R5 verification — Save is NOT gated by Terms acceptance Technique: Equivalence Partitioning Req: Overview R5; Customer Detail §5.1 validation #40 removed; FR-18; RG-01, RG-02 | D29: Account Creation form open in Insert mode (AS-03). Addresses RG-01/RG-02 (feature claims Save is Terms-gated; BRD removes the gate). | E29: Chrome (latest) | F29: 1. Enter only the mandatory contact fields. 2. Without accepting any Terms (none should exist), click Save. | G29: First = "Ada"; Last = "Nash"; Email = "ada.nash@example.com"; no terms interaction available/performed. | H29: Save proceeds and creates the customer using only the documented validations (#10, #20, #30, #50, #60, #70, #80); no IsTermsAccepted validation (#40) blocks Save. Any Terms-based blocking indicates the feature-vs-BRD conflict (RG-01). | J29: High
A30: Boundary Value Analysis — phone 10-digit minimum boundaries
A31: US-CI-06 | B31: TC-011 | C31: Home Phone with 9 digits is rejected (just below minimum) Technique: Boundary Value Analysis Req: Customer Detail §5.1 validation #10 "Home Phone Number 10 Digits Min"; FR-09 | D31: Account Creation form open in Insert mode (AS-03). | E31: Chrome (latest) | F31: 1. Enter valid mandatory fields. 2. Enter a Home Phone with 9 digits. 3. Click Save. | G31: Mandatory fields valid; Home Phone = "202555010" (9 digits). | H31: Save is blocked by validation #10 "Home Phone Number 10 Digits Min"; no customer is created. | J31: High
A32: US-CI-06 | B32: TC-012 | C32: Home Phone with exactly 10 digits is accepted (minimum boundary) Technique: Boundary Value Analysis Req: Customer Detail §5.1 validation #10, action #10; FR-09, FR-13 | D32: Account Creation form open in Insert mode (AS-03). | E32: Chrome (latest) | F32: 1. Enter valid mandatory fields. 2. Enter a Home Phone with exactly 10 digits. 3. Click Save. | G32: Mandatory fields valid; Home Phone = "2025550100" (10 digits). | H32: Validation #10 passes; the customer is created; the home phone is normalised on Save (action #10). | J32: High
A33: US-CI-06 | B33: TC-013 | C33: Home Phone with 11 digits is accepted (above minimum) Technique: Boundary Value Analysis Req: Customer Detail §5.1 validation #10, §3.1 FormattedCellPhone; FR-09; RG-04 | D33: Account Creation form open in Insert mode (AS-03); upper bound undefined (RG-04). | E33: Chrome (latest) | F33: 1. Enter valid mandatory fields. 2. Enter a Home Phone with 11 digits. 3. Click Save. | G33: Mandatory fields valid; Home Phone = "12025550100" (11 digits). | H33: Validation #10 (minimum) passes and the customer is created. Normalisation formats only the first 10 digits (RG-04) — observe handling of the 11th digit and raise a defect/clarification if truncation is unintended. | J33: Medium
A34: US-CI-06 | B34: TC-014 | C34: Mobile Phone with 9 digits is rejected (just below minimum) Technique: Boundary Value Analysis Req: Customer Detail §5.1 validation #20 "Cell Phone Number 10 Digits Min"; FR-10 | D34: Account Creation form open in Insert mode (AS-03). | E34: Chrome (latest) | F34: 1. Enter valid mandatory fields. 2. Enter a Mobile Phone with 9 digits. 3. Click Save. | G34: Mandatory fields valid; Mobile Country Code = "+1"; Mobile Phone = "202555011" (9 digits). | H34: Save is blocked by validation #20 "Cell Phone Number 10 Digits Min"; no customer is created. | J34: High
A35: US-CI-06 | B35: TC-015 | C35: Mobile Phone with exactly 10 digits is accepted (minimum boundary) Technique: Boundary Value Analysis Req: Customer Detail §5.1 validation #20, action #20, §3.1 FormattedCellPhone; FR-10, FR-13 | D35: Account Creation form open in Insert mode (AS-03). | E35: Chrome (latest) | F35: 1. Enter valid mandatory fields. 2. Enter a Mobile Phone with exactly 10 digits. 3. Click Save. | G35: Mandatory fields valid; Mobile Country Code = "+1"; Mobile Phone = "2025550111" (10 digits). | H35: Validation #20 passes; the customer is created; the cell phone is normalised to the "(xxx) xxx-xxxx" pattern on Save (action #20, AS-06). | J35: High
A36: US-CI-06 | B36: TC-016 | C36: Mobile Phone with 11 digits is accepted (above minimum) Technique: Boundary Value Analysis Req: Customer Detail §5.1 validation #20, §3.1 FormattedCellPhone; FR-10; RG-04 | D36: Account Creation form open in Insert mode (AS-03); upper bound undefined (RG-04). | E36: Chrome (latest) | F36: 1. Enter valid mandatory fields. 2. Enter a Mobile Phone with 11 digits. 3. Click Save. | G36: Mandatory fields valid; Mobile Phone = "12025550111" (11 digits). | H36: Validation #20 (minimum) passes and the customer is created. Observe normalisation of digits beyond the first 10 (RG-04) and raise clarification if truncation is unintended. | J36: Medium
A37: Decision Table Testing — Save Customer Details rule combinations
A38: US-CI-06 | B38: TC-017 | C38: Decision Table Rule 1 — all required valid, email unique, phones valid: Save succeeds Technique: Decision Table Testing Req: Customer Detail §5.1 (all validations pass path); US-CI-06; FR-16 | D38: Account Creation form open in Insert mode (AS-03). Conditions: First=T, Last=T, Email present=T, format valid=T, brand-unique=T, entered phones ≥10 digits=T. | E38: Chrome (latest) | F38: 1. Populate all fields to satisfy every "T" condition. 2. Click Save. | G38: First = "Owen"; Last = "Park"; Email = "owen.park@example.com"; Home Phone = "2025550100"; Mobile Phone = "2025550111". | H38: Action = customer created and set as current (all 8 validations pass; commit actions execute). | J38: High
A39: US-CI-06 | B39: TC-018 | C39: Decision Table Rule 2 — Last Name missing (others valid): Save fails Technique: Decision Table Testing Req: Customer Detail §5.1 validation #60; FR-05 | D39: Account Creation form open in Insert mode (AS-03). Conditions: First=T, Last=F, Email present/valid/unique=T. | E39: Chrome (latest) | F39: 1. Enter First and a valid Email; leave Last Name empty. 2. Click Save. | G39: First = "Owen"; Last = ""; Email = "owen.park2@example.com". | H39: Action = creation blocked at validation #60 "Last Name Missing"; no customer created. | J39: High
A40: US-CI-06 | B40: TC-019 | C40: Decision Table Rule 3 — names present but Email format invalid: Save fails Technique: Decision Table Testing Req: Customer Detail §5.1 validation #70; FR-07 | D40: Account Creation form open in Insert mode (AS-03). Conditions: First=T, Last=T, Email present=T, format valid=F. | E40: Chrome (latest) | F40: 1. Enter valid names and a malformed Email. 2. Click Save. | G40: First = "Owen"; Last = "Park"; Email = "owen.park@@example" (malformed). | H40: Action = creation blocked at validation #70 "email address format"; no customer created. | J40: High
A41: US-CI-06 | B41: TC-020 | C41: Decision Table Rule 4 — email valid format but duplicate within brand: Save fails Technique: Decision Table Testing Req: Customer Detail §5.1 validation #80, §3.1 (brand-scoped WHERE); FR-08 | D41: Account Creation form open in Insert mode (AS-03). A customer with the same email already exists in the current brand. Conditions: First=T, Last=T, Email present=T, format valid=T, brand-unique=F. | E41: Chrome (latest) | F41: 1. Enter valid names. 2. Enter an email that already exists for another customer in the current brand. 3. Click Save. | G41: First = "Owen"; Last = "Park"; Email = "existing.customer@example.com" (already present in this brand). | H41: Action = creation blocked at validation #80 "Duplicate Brand Email Address"; no duplicate customer created within the brand. | J41: High
A42: US-CI-06 | B42: TC-021 | C42: Decision Table Rule 5 — all required valid but entered Home Phone below 10 digits: Save fails Technique: Decision Table Testing Req: Customer Detail §5.1 validation #10; FR-09 | D42: Account Creation form open in Insert mode (AS-03). Conditions: First/Last/Email valid=T, entered Home Phone ≥10 digits=F. | E42: Chrome (latest) | F42: 1. Enter valid mandatory fields. 2. Enter a Home Phone with fewer than 10 digits. 3. Click Save. | G42: First = "Owen"; Last = "Park"; Email = "owen.park3@example.com"; Home Phone = "202555" (6 digits). | H42: Action = creation blocked at validation #10 "Home Phone Number 10 Digits Min" despite valid name/email; no customer created. | J42: Medium
A43: State Transition Testing — Insert / Validation-Failed / Committed states
A44: US-CI-06 | B44: TC-029 | C44: State transition — invalid Save keeps the form active, then correction commits Technique: State Transition Testing Req: Customer Detail §1.2 (Insert mode), §5.1 validation #30; FR-01, FR-06 | D44: Account Creation form open in Insert mode (AS-03). States: S1 Empty Insert form → S2 Data Entered → S3 Validation Failed → S4 Committed. | E44: Chrome (latest) | F44: 1. From S1, enter names but leave Email empty (S2). 2. Click Save — expect transition to S3 (Validation Failed). 3. Enter a valid Email. 4. Click Save again — expect transition to S4 (Committed). | G44: Step-1 invalid: First = "Kate"; Last = "Doe"; Email = "" (empty). Step-2 correction: Email = "kate.doe@example.com". | H44: The first Save transitions to Validation Failed (blocked by #30, no commit, form remains editable with data retained); after correction, Save transitions to Committed and the customer is created and set as current. No invalid intermediate state persists a customer. | J44: High
A45: US-CI-06 | B45: TC-030 | C45: State transition — successful Save stamps brand context and current customer Technique: State Transition Testing Req: Customer Detail §5.1 actions #5/#8/#10/#20/#30/#50/#60, §1.0 postcondition; FR-15; (action #40 removed — R5) | D45: Account Creation form open in Insert mode (AS-03). Transition: Data Entered (valid) → Committed → Current-customer context established. | E45: Chrome (latest) | F45: 1. Enter valid mandatory fields. 2. Click Save. 3. Observe the resulting context. | G45: First = "Mark"; Last = "Lane"; Email = "mark.lane@example.com". | H45: On the transition to Committed, the Save actions execute in order: BrandID stamped to CurrentBrandID (#5), CustomerBrand link inserted (#8), phone/country-code normalised (#10/#20/#30), event copied (#50), and UserParam.CurrentCustomerID set to the new customer (#60). The flow continues with the new customer selected (AS-07). Action #40 (Terms) is de-scoped per R5 and must NOT execute. | J45: High
A46: Use Case Testing — end-to-end create-account workflow & navigation
A47: US-CI-06 | B47: TC-031 | C47: End-to-end — search with no match, create account, and continue into the scan/shop flow Technique: Use Case Testing Req: Overview US-CI-01, US-CI-02, US-CI-03, US-CI-06, US-CI-05; Customer Detail §1.0; FR-17 | D47: User authenticated with a brand context set (AS-03). Customer Search panel accessible (US-CI-01). | E47: Chrome (latest) | F47: 1. Open the Customer Search panel (US-CI-01). 2. Search by first + last name returning no match (US-CI-02). 3. Click Create Account to branch to the form (US-CI-03 → US-CI-06). 4. Complete the mandatory fields and click Save. 5. Observe that the new customer becomes the current customer. | G47: Search: First = "Zoe", Last = "West" (no existing match). Create: First = "Zoe"; Last = "West"; Email = "zoe.west@example.com". | H47: The customer is created, stamped to the brand, linked via CustomerBrand, and set as UserParam.CurrentCustomerID; the associate continues with the new customer selected, entering the downstream scan/shop workspace (as with an existing customer via Search Results → Scan, US-CI-05). | J47: High
...
